<?xml version="1.0"?>
<runHistory script="index">
 <run>
  <RunDate>2018-02-18 23:28:01.599 -0600</RunDate>
  <Status>Failure</Status>
  <Duration>0.301784</Duration>
  <Errors>1</Errors>
  <Warnings>0</Warnings>
  <Exceptions>0</Exceptions>
  <Successes>0</Successes>
  <LogFile>20180218_232801.599/LogFile.txt</LogFile>
  <ReturnValue></ReturnValue>
  <ErrorMessage>STUnknownMessage -- ERROR: No Such Command: &#x27;foo&#x27;</ErrorMessage>
 </run>
 <run>
  <RunDate>2018-02-18 23:28:13.296 -0600</RunDate>
  <Status>Failure</Status>
  <Duration>0.241302</Duration>
  <Errors>1</Errors>
  <Warnings>0</Warnings>
  <Exceptions>0</Exceptions>
  <Successes>0</Successes>
  <LogFile>20180218_232813.296/LogFile.txt</LogFile>
  <ReturnValue></ReturnValue>
  <ErrorMessage>SenseTalk Compiler Exception -- in foo:
Warning at line 6: Warning - EXIT REPEAT command used outside a Repeat loop</ErrorMessage>
 </run>
 <run>
  <RunDate>2018-02-18 23:28:25.873 -0600</RunDate>
  <Status>Failure</Status>
  <Duration>0.236262</Duration>
  <Errors>1</Errors>
  <Warnings>0</Warnings>
  <Exceptions>0</Exceptions>
  <Successes>0</Successes>
  <LogFile>20180218_232825.873/LogFile.txt</LogFile>
  <ReturnValue></ReturnValue>
  <ErrorMessage>SenseTalk Compiler Exception -- in foo:
Warning at line 6: Warning - EXIT REPEAT command used outside a Repeat loop</ErrorMessage>
 </run>
 <run>
  <RunDate>2018-02-18 23:28:33.053 -0600</RunDate>
  <Status>Failure</Status>
  <Duration>0.211726</Duration>
  <Errors>1</Errors>
  <Warnings>0</Warnings>
  <Exceptions>0</Exceptions>
  <Successes>0</Successes>
  <LogFile>20180218_232833.053/LogFile.txt</LogFile>
  <ReturnValue></ReturnValue>
  <ErrorMessage>SenseTalk Compiler Exception -- in foo:
Warning at line 6: Warning - EXIT REPEAT command used outside a Repeat loop</ErrorMessage>
 </run>
 <run>
  <RunDate>2018-02-18 23:28:51.661 -0600</RunDate>
  <Status>Failure</Status>
  <Duration>0.229086</Duration>
  <Errors>1</Errors>
  <Warnings>0</Warnings>
  <Exceptions>0</Exceptions>
  <Successes>0</Successes>
  <LogFile>20180218_232851.661/LogFile.txt</LogFile>
  <ReturnValue></ReturnValue>
  <ErrorMessage>SenseTalk Compiler Exception -- in foo:
Warning at line 6: Warning - Wrong handler name: function</ErrorMessage>
 </run>
 <run>
  <RunDate>2018-02-18 23:29:19.555 -0600</RunDate>
  <Status>Failure</Status>
  <Duration>1.301138</Duration>
  <Errors>1</Errors>
  <Warnings>0</Warnings>
  <Exceptions>0</Exceptions>
  <Successes>0</Successes>
  <LogFile>20180218_232919.555/LogFile.txt</LogFile>
  <ReturnValue></ReturnValue>
  <ErrorMessage>STMaxCallDepthExceeded -- Handlers were called to a depth exceeding the maximum limit (40). HINT: One common cause for this error is a script that has been given the same name as a built-in command or function unintentionally calling itself.</ErrorMessage>
 </run>
 <run>
  <RunDate>2018-02-18 23:29:26.198 -0600</RunDate>
  <Status>Success</Status>
  <Duration>0.240333</Duration>
  <Errors>0</Errors>
  <Warnings>0</Warnings>
  <Exceptions>0</Exceptions>
  <Successes>1</Successes>
  <LogFile>20180218_232926.198/LogFile.txt</LogFile>
  <ReturnValue></ReturnValue>
  <ErrorMessage></ErrorMessage>
 </run>
 <run>
  <RunDate>2018-02-18 23:29:32.462 -0600</RunDate>
  <Status>Failure</Status>
  <Duration>1.199051</Duration>
  <Errors>1</Errors>
  <Warnings>0</Warnings>
  <Exceptions>0</Exceptions>
  <Successes>0</Successes>
  <LogFile>20180218_232932.462/LogFile.txt</LogFile>
  <ReturnValue></ReturnValue>
  <ErrorMessage>STMaxCallDepthExceeded -- Handlers were called to a depth exceeding the maximum limit (40). HINT: One common cause for this error is a script that has been given the same name as a built-in command or function unintentionally calling itself.</ErrorMessage>
 </run>
 <run>
  <RunDate>2018-02-18 23:29:51.432 -0600</RunDate>
  <Status>Failure</Status>
  <Duration>1.492656</Duration>
  <Errors>1</Errors>
  <Warnings>0</Warnings>
  <Exceptions>0</Exceptions>
  <Successes>0</Successes>
  <LogFile>20180218_232951.432/LogFile.txt</LogFile>
  <ReturnValue></ReturnValue>
  <ErrorMessage>STMaxCallDepthExceeded -- Handlers were called to a depth exceeding the maximum limit (40). HINT: One common cause for this error is a script that has been given the same name as a built-in command or function unintentionally calling itself.</ErrorMessage>
 </run>
 <run>
  <RunDate>2018-02-18 23:30:02.919 -0600</RunDate>
  <Status>Success</Status>
  <Duration>0.472003</Duration>
  <Errors>0</Errors>
  <Warnings>0</Warnings>
  <Exceptions>0</Exceptions>
  <Successes>1</Successes>
  <LogFile>20180218_233002.919/LogFile.txt</LogFile>
  <ReturnValue></ReturnValue>
  <ErrorMessage></ErrorMessage>
 </run>
 <run>
  <RunDate>2018-02-18 23:30:25.923 -0600</RunDate>
  <Status>Success</Status>
  <Duration>0.426878</Duration>
  <Errors>0</Errors>
  <Warnings>0</Warnings>
  <Exceptions>0</Exceptions>
  <Successes>1</Successes>
  <LogFile>20180218_233025.923/LogFile.txt</LogFile>
  <ReturnValue></ReturnValue>
  <ErrorMessage></ErrorMessage>
 </run>
 <run>
  <RunDate>2018-02-18 23:31:34.106 -0600</RunDate>
  <Status>Success</Status>
  <Duration>0.287464</Duration>
  <Errors>0</Errors>
  <Warnings>0</Warnings>
  <Exceptions>0</Exceptions>
  <Successes>1</Successes>
  <LogFile>20180218_233134.106/LogFile.txt</LogFile>
  <ReturnValue></ReturnValue>
  <ErrorMessage></ErrorMessage>
 </run>
 <run>
  <RunDate>2018-02-18 23:31:55.317 -0600</RunDate>
  <Status>Success</Status>
  <Duration>0.227128</Duration>
  <Errors>0</Errors>
  <Warnings>0</Warnings>
  <Exceptions>0</Exceptions>
  <Successes>1</Successes>
  <LogFile>20180218_233155.317/LogFile.txt</LogFile>
  <ReturnValue></ReturnValue>
  <ErrorMessage></ErrorMessage>
 </run>
 <run>
  <RunDate>2018-02-18 23:31:59.534 -0600</RunDate>
  <Status>Failure</Status>
  <Duration>0.236351</Duration>
  <Errors>1</Errors>
  <Warnings>0</Warnings>
  <Exceptions>0</Exceptions>
  <Successes>0</Successes>
  <LogFile>20180218_233159.534/LogFile.txt</LogFile>
  <ReturnValue></ReturnValue>
  <ErrorMessage>STUnknownMessage -- ERROR: No Such Command: &#x27;foo&#x27;</ErrorMessage>
 </run>
 <run>
  <RunDate>2018-02-18 23:32:18.050 -0600</RunDate>
  <Status>Success</Status>
  <Duration>0.446202</Duration>
  <Errors>0</Errors>
  <Warnings>0</Warnings>
  <Exceptions>0</Exceptions>
  <Successes>1</Successes>
  <LogFile>20180218_233218.050/LogFile.txt</LogFile>
  <ReturnValue></ReturnValue>
  <ErrorMessage></ErrorMessage>
 </run>
 <run>
  <RunDate>2018-02-18 23:32:24.271 -0600</RunDate>
  <Status>Success</Status>
  <Duration>0.447729</Duration>
  <Errors>0</Errors>
  <Warnings>0</Warnings>
  <Exceptions>0</Exceptions>
  <Successes>1</Successes>
  <LogFile>20180218_233224.271/LogFile.txt</LogFile>
  <ReturnValue></ReturnValue>
  <ErrorMessage></ErrorMessage>
 </run>
 <run>
  <RunDate>2018-02-18 23:33:01.003 -0600</RunDate>
  <Status>Failure</Status>
  <Duration>1.098304</Duration>
  <Errors>1</Errors>
  <Warnings>0</Warnings>
  <Exceptions>0</Exceptions>
  <Successes>0</Successes>
  <LogFile>20180218_233301.003/LogFile.txt</LogFile>
  <ReturnValue></ReturnValue>
  <ErrorMessage>STMaxCallDepthExceeded -- Handlers were called to a depth exceeding the maximum limit (40). HINT: One common cause for this error is a script that has been given the same name as a built-in command or function unintentionally calling itself.</ErrorMessage>
 </run>
 <run>
  <RunDate>2018-02-18 23:33:18.590 -0600</RunDate>
  <Status>Success</Status>
  <Duration>0.497700</Duration>
  <Errors>0</Errors>
  <Warnings>0</Warnings>
  <Exceptions>0</Exceptions>
  <Successes>1</Successes>
  <LogFile>20180218_233318.590/LogFile.txt</LogFile>
  <ReturnValue></ReturnValue>
  <ErrorMessage></ErrorMessage>
 </run>
 <run>
  <RunDate>2018-02-18 23:33:30.032 -0600</RunDate>
  <Status>Success</Status>
  <Duration>0.542942</Duration>
  <Errors>0</Errors>
  <Warnings>0</Warnings>
  <Exceptions>0</Exceptions>
  <Successes>1</Successes>
  <LogFile>20180218_233330.032/LogFile.txt</LogFile>
  <ReturnValue></ReturnValue>
  <ErrorMessage></ErrorMessage>
 </run>
 <run>
  <RunDate>2018-02-18 23:35:21.833 -0600</RunDate>
  <Status>Success</Status>
  <Duration>0.528294</Duration>
  <Errors>0</Errors>
  <Warnings>0</Warnings>
  <Exceptions>0</Exceptions>
  <Successes>1</Successes>
  <LogFile>20180218_233521.833/LogFile.txt</LogFile>
  <ReturnValue></ReturnValue>
  <ErrorMessage></ErrorMessage>
 </run>
 <run>
  <RunDate>2018-02-18 23:35:44.633 -0600</RunDate>
  <Status>Success</Status>
  <Duration>0.271226</Duration>
  <Errors>0</Errors>
  <Warnings>0</Warnings>
  <Exceptions>0</Exceptions>
  <Successes>1</Successes>
  <LogFile>20180218_233544.633/LogFile.txt</LogFile>
  <ReturnValue></ReturnValue>
  <ErrorMessage></ErrorMessage>
 </run>
 <run>
  <RunDate>2018-02-18 23:35:58.845 -0600</RunDate>
  <Status>Success</Status>
  <Duration>0.462941</Duration>
  <Errors>0</Errors>
  <Warnings>0</Warnings>
  <Exceptions>0</Exceptions>
  <Successes>1</Successes>
  <LogFile>20180218_233558.845/LogFile.txt</LogFile>
  <ReturnValue></ReturnValue>
  <ErrorMessage></ErrorMessage>
 </run>
 <run>
  <RunDate>2018-02-18 23:36:03.897 -0600</RunDate>
  <Status>Success</Status>
  <Duration>0.398404</Duration>
  <Errors>0</Errors>
  <Warnings>0</Warnings>
  <Exceptions>0</Exceptions>
  <Successes>1</Successes>
  <LogFile>20180218_233603.897/LogFile.txt</LogFile>
  <ReturnValue></ReturnValue>
  <ErrorMessage></ErrorMessage>
 </run>
 <run>
  <RunDate>2019-03-11 09:43:20.449 -0600</RunDate>
  <Status>Success</Status>
  <Duration>0.341738</Duration>
  <Errors>0</Errors>
  <Warnings>0</Warnings>
  <Exceptions>0</Exceptions>
  <Successes>1</Successes>
  <LogFile>20190311_094320.449/LogFile.txt</LogFile>
  <ReturnValue></ReturnValue>
  <ErrorMessage></ErrorMessage>
 </run>
 <run>
  <RunDate>2020-10-07 10:19:57.835 -0600</RunDate>
  <Status>Success</Status>
  <Duration>0.898595</Duration>
  <Errors>0</Errors>
  <Warnings>0</Warnings>
  <Exceptions>0</Exceptions>
  <Successes>1</Successes>
  <LogFile>20201007_101957.835/LogFile.txt</LogFile>
  <ReturnValue></ReturnValue>
  <ErrorMessage></ErrorMessage>
 </run>
</runHistory>
